Workbook

Sheet Read_First
A2: Data Analysis Tool Author: Dr. Martin Schrepp
A3: The goal of this tool is to make the analysis of UEQ (User Experience Questionnaire) data as easy as possible for you. You simply enter the data obtained from your respondents into the Data worksheet. The tool then automatically calculates all statistics necessary to interpret the results. In addition, several graphs are shown that you may want to use in your result presentations. Simply copy them to your word processor of presentation tool. The instructions in this tool are in English. To make the interpretation of the results easier and to have the charts in your language you can switch the language in the following dropdown. This will only switch the items and scale names, not the instructions in the Excel.
A5: Choose your Language: | B5: English
A7: Please Note: Changing the language will show the UEQ items and the UEQ dimensions in the selected language. All other texts will remain in English.
A9: The tool contains the following work sheets: Data: Here you can enter the raw data of your evaluation. This is the only work sheet that you need to modify. Do not change the content of the other work sheets, you may destroy unintentionally some of the formulas in the cells! DT: The order of the items (i.e. if the positive term is left or right in an item) is randomized in the questionnaire to minimized answer tendencies. Here the items are changed to a common order (negative term left, positive term right). The transformed data are used for all the further calculations. Results: Main results of the questionnaire. Here the scale means and the mean and standard deviation per item are calculated. Confidence_Intervals: Confidence intervals for the scale means and for the mean of each item are calculated. Answer_Distributions: Here you can see the distributions of the answers (values 1 to 7) for the single items. This can help to find items that show a ploarization of opinions, i.e. where many negative and many positive answers can be found. Scale_Consistency: Here the Cronbach-Alpha Coefficient and Guttmans Lambda2 coefficient per scale are calculated. Check here if the scales have a sufficiently high values. Scales with a small value (<0.5) should be treated carefully in the interpretation (if you have only a small sample size (< 50 responses) then interpret these values very carefully. In such cases a small value for these coefficients may result solely from sampling effects and may not indicate a real problem. Benchmark: The benchmark shows you in an easy way how good the evaluated product is compared to the products in the benchmark data set. There is also a graphic that shows for each scale how the results are related to the products in the benchmark data set. Inconsistencies: On this work sheet the data are analysed for inconsistent answers, i.e. answers from participants that answered at least a part of the items randomly. You may want to remove these data before you calculate the results. Sample_Size: If you observe big error bars concerning the scale means you may ask yourself if you need to collect additional data. This sheet helps you to estimate how many data you need in order to reach a certain precision. KPI_Calculation: There is an extension of the UEQ with 6 additional questions. This extension allows to calculate a KPI (single number representing the overall user experience). This work sheet is only relevant if you used this extension. It allows to enter the data obtained for the 6 additional questions and calculates the KPI. Items: Contains the item and dimension names in the different languages. Used for switching the language. Please do not modify date in this sheet.

Sheet Data
A1: Please enter the data here! Use the item numbers in the printed questionnaire and the categories 1 (if the alternative on the extreme left is marked) to 7 (if the alternative on the extreme right is marked). Leave the cell empty if the person has not answered the item. Please do not enter a special caracter in such cases, since this would cause errors in the calculations. You can enter data for a maximum of 1000 participants. If you need more, you have to adjust the fomulas in the Excel. The data analysis tool is delivered with some example data in this work sheet. Simply delete them before you enter your data here.
A2: Items
A3: 1 | B3: 2 | C3: 3 | D3: 4 | E3: 5 | F3: 6 | G3: 7 | H3: 8 | I3: 9 | J3: 10 | K3: 11 | L3: 12 | M3: 13 | N3: 14 | O3: 15 | P3: 16 | Q3: 17 | R3: 18 | S3: 19 | T3: 20 | U3: 21 | V3: 22 | W3: 23 | X3: 24 | Y3: 25 | Z3: 26
A4: 6 | B4: 7 | C4: 2 | D4: 1 | E4: 2 | F4: 6 | G4: 6 | H4: 6 | I4: 2 | J4: 3 | K4: 6 | L4: 2 | M4: 5 | N4: 6 | O4: 5 | P4: 5 | Q4: 2 | R4: 2 | S4: 2 | T4: 6 | U4: 2 | V4: 6 | W4: 2 | X4: 2 | Y4: 2 | Z4: 6
A5: 7 | B5: 7 | C5: 1 | D5: 1 | E5: 1 | F5: 7 | G5: 7 | H5: 7 | I5: 1 | J5: 1 | K5: 7 | L5: 1 | M5: 7 | N5: 7 | O5: 1 | P5: 7 | Q5: 1 | R5: 1 | S5: 1 | T5: 7 | U5: 1 | V5: 7 | W5: 1 | X5: 1 | Y5: 1 | Z5: 1
A6: 7 | B6: 7 | C6: 2 | D6: 1 | E6: 1 | F6: 5 | G6: 6 | H6: 2 | I6: 2 | J6: 2 | K6: 5 | L6: 1 | M6: 5 | N6: 6 | O6: 6 | P6: 6 | Q6: 2 | R6: 3 | S6: 2 | T6: 6 | U6: 3 | V6: 6 | W6: 2 | X6: 3 | Y6: 3 | Z6: 6
A7: 6 | B7: 6 | C7: 4 | D7: 2 | E7: 3 | F7: 4 | G7: 4 | H7: 6 | I7: 2 | J7: 3 | K7: 5 | L7: 1 | M7: 7 | N7: 5 | O7: 6 | P7: 6 | Q7: 1 | R7: 4 | S7: 1 | T7: 7 | U7: 1 | V7: 6 | W7: 2 | X7: 4 | Y7: 3 | Z7: 4
A8: 6 | B8: 3 | C8: 4 | D8: 5 | E8: 2 | F8: 4 | G8: 5 | H8: 5 | I8: 2 | J8: 4 | K8: 5 | L8: 2 | M8: 5 | N8: 5 | O8: 4 | P8: 5 | Q8: 2 | R8: 3 | S8: 2 | T8: 6 | U8: 3 | V8: 6 | W8: 2 | X8: 3 | Y8: 3 | Z8: 4
A9: 3 | B9: 6 | C9: 2 | D9: 7 | E9: 4 | F9: 4 | G9: 4 | H9: 6 | I9: 2 | J9: 4 | K9: 4 | L9: 4 | M9: 4 | N9: 3 | O9: 4 | P9: 3 | Q9: 5 | R9: 5 | S9: 4 | T9: 4 | U9: 2 | V9: 6 | W9: 2 | X9: 4 | Y9: 3 | Z9: 6
A10: 7 | B10: 5 | C10: 4 | D10: 5 | E10: 1 | F10: 4 | G10: 5 | H10: 4 | I10: 3 | J10: 3 | K10: 6 | L10: 1 | M10: 6 | N10: 7 | O10: 4 | P10: 7 | Q10: 1 | R10: 3 | S10: 1 | T10: 7 | U10: 2 | V10: 6 | W10: 2 | X10: 4 | Y10: 1 | Z10: 6
A11: 5 | B11: 6 | C11: 4 | D11: 3 | E11: 1 | F11: 4 | G11: 4 | H11: 6 | I11: 3 | J11: 2 | K11: 4 | L11: 3 | M11: 6 | N11: 4 | O11: 6 | P11: 5 | Q11: 1 | R11: 4 | S11: 2 | T11: 5 | U11: 1 | V11: 7 | W11: 3 | X11: 4 | Y11: 4 | Z11: 5
A12: 7 | B12: 7 | C12: 1 | D12: 1 | E12: 1 | F12: 5 | G12: 6 | H12: 4 | I12: 1 | J12: 4 | K12: 4 | L12: 1 | M12: 7 | N12: 7 | O12: 7 | P12: 7 | Q12: 2 | R12: 4 | S12: 1 | T12: 7 | U12: 2 | V12: 7 | W12: 3 | X12: 1 | Y12: 1 | Z12: 4
A13: 6 | B13: 7 | C13: 6 | D13: 6 | E13: 5 | F13: 5 | G13: 5 | H13: 3 | I13: 5 | J13: 6 | K13: 6 | L13: 1 | M13: 7 | N13: 6 | O13: 5 | P13: 6 | Q13: 2 | R13: 2 | S13: 2 | T13: 6 | U13: 1 | V13: 7 | W13: 1 | X13: 2 | Y13: 1 | Z13: 1
A14: 5 | B14: 5 | C14: 6 | D14: 6 | E14: 2 | F14: 4 | G14: 5 | H14: 3 | I14: 4 | J14: 2 | K14: 5 | L14: 3 | M14: 5 | N14: 5 | O14: 5 | P14: 5 | Q14: 1 | R14: 4 | S14: 2 | T14: 5 | U14: 3 | V14: 5 | W14: 6 | X14: 2 | Y14: 2 | Z14: 6
... A258: 7 | B258: 5 | C258: 3 | D258: 3 | E258: 1 | F258: 6 | G258: 6 | H258: 4 | I258: 3 | J258: 2 | K258: 4 | L258: 1 | M258: 6 | N258: 6 | O258: 2 | P258: 6 | Q258: 6 | R258: 1 | S258: 2 | T258: 7 | U258: 1 | V258: 4 | W258: 2 | X258: 2 | Y258: 2 | Z258: 2

Sheet DT
A1: Transformed Data The order of the positive and negative term for an item is randomized in the questionnaire. Per dimension half of the items start with the positive and half with the negative term. Here you can find the transformed values per item. You can use these values for example for own statistical calculations. The +3 represent the most positive and the -3 the most negative value.
A2: Items | AC2: Scale means per person
A3: 1 | B3: 2 | C3: 3 | D3: 4 | E3: 5 | F3: 6 | G3: 7 | H3: 8 | I3: 9 | J3: 10 | K3: 11 | L3: 12 | M3: 13 | N3: 14 | O3: 15 | P3: 16 | Q3: 17 | R3: 18 | S3: 19 | T3: 20 | U3: 21 | V3: 22 | W3: 23 | X3: 24 | Y3: 25 | Z3: 26 | AC3: =VLOOKUP(Read_First!B5,Items!A1:BI50,54,FALSE) -> Attractiveness | AD3: =VLOOKUP(Read_First!B5,Items!A1:BI50,55,FALSE) -> Perspicuity | AE3: =VLOOKUP(Read_First!B5,Items!A1:BI50,56,FALSE) -> Efficiency | AF3: =VLOOKUP(Read_First!B5,Items!A1:BI50,57,FALSE) -> Dependability | AG3: =VLOOKUP(Read_First!B5,Items!A1:BI50,58,FALSE) -> Stimulation | AH3: =VLOOKUP(Read_First!B5,Items!A1:BI50,59,FALSE) -> Novelty
A4: =IF(Data!A4>0,Data!A4-4,"") -> 2 | B4: =IF(Data!B4>0,Data!B4-4,"") -> 3 | C4: =IF(Data!C4>0,4-Data!C4,"") -> 2 | D4: =IF(Data!D4>0,4-Data!D4,"") -> 3 | E4: =IF(Data!E4>0,4-Data!E4,"") -> 2 | F4: =IF(Data!F4>0,Data!F4-4,"") -> 2 | G4: =IF(Data!G4>0,Data!G4-4,"") -> 2 | H4: =IF(Data!H4>0,Data!H4-4,"") -> 2 | I4: =IF(Data!I4>0,4-Data!I4,"") -> 2 | J4: =IF(Data!J4>0,4-Data!J4,"") -> 1 | K4: =IF(Data!K4>0,Data!K4-4,"") -> 2 | L4: =IF(Data!L4>0,4-Data!L4,"") -> 2 | M4: =IF(Data!M4>0,Data!M4-4,"") -> 1 | N4: =IF(Data!N4>0,Data!N4-4,"") -> 2 | O4: =IF(Data!O4>0,Data!O4-4,"") -> 1 | P4: =IF(Data!P4>0,Data!P4-4,"") -> 1 | Q4: =IF(Data!Q4>0,4-Data!Q4,"") -> 2 | R4: =IF(Data!R4>0,4-Data!R4,"") -> 2 | S4: =IF(Data!S4>0,4-Data!S4,"") -> 2 | T4: =IF(Data!T4>0,Data!T4-4,"") -> 2 | U4: =IF(Data!U4>0,4-Data!U4,"") -> 2 | V4: =IF(Data!V4>0,Data!V4-4,"") -> 2 | W4: =IF(Data!W4>0,4-Data!W4,"") -> 2 | X4: =IF(Data!X4>0,4-Data!X4,"") -> 2 | Y4: =IF(Data!Y4>0,4-Data!Y4,"") -> 2 | Z4: =IF(Data!Z4>0,Data!Z4-4,"") -> 2 | AC4: =IF(COUNT(A4,L4,N4,P4,X4,Y4)>0,AVERAGE(A4,L4,N4,P4,X4,Y4),"") -> 1.8333333 | AD4: =IF(COUNT(B4,D4,M4,U4)>0,AVERAGE(B4,D4,M4,U4),"") -> 2.25 | AE4: =IF(COUNT(I4,T4,V4,W4)>0,AVERAGE(I4,T4,V4,W4),"") -> 2 | AF4: =IF(COUNT(H4,K4,Q4,S4)>0,AVERAGE(H4,K4,Q4,S4),"") -> 2 | AG4: =IF(COUNT(E4,F4,G4,R4)>0,AVERAGE(E4,F4,G4,R4),"") -> 2 | AH4: =IF(COUNT(C4,J4,O4,Z4)>0,AVERAGE(C4,J4,O4,Z4),"") -> 1.5
A5: =IF(Data!A5>0,Data!A5-4,"") -> 3 | B5: =IF(Data!B5>0,Data!B5-4,"") -> 3 | C5: =IF(Data!C5>0,4-Data!C5,"") -> 3 | D5: =IF(Data!D5>0,4-Data!D5,"") -> 3 | E5: =IF(Data!E5>0,4-Data!E5,"") -> 3 | F5: =IF(Data!F5>0,Data!F5-4,"") -> 3 | G5: =IF(Data!G5>0,Data!G5-4,"") -> 3 | H5: =IF(Data!H5>0,Data!H5-4,"") -> 3 | I5: =IF(Data!I5>0,4-Data!I5,"") -> 3 | J5: =IF(Data!J5>0,4-Data!J5,"") -> 3 | K5: =IF(Data!K5>0,Data!K5-4,"") -> 3 | L5: =IF(Data!L5>0,4-Data!L5,"") -> 3 | M5: =IF(Data!M5>0,Data!M5-4,"") -> 3 | N5: =IF(Data!N5>0,Data!N5-4,"") -> 3 | O5: =IF(Data!O5>0,Data!O5-4,"") -> -3 | P5: =IF(Data!P5>0,Data!P5-4,"") -> 3 | Q5: =IF(Data!Q5>0,4-Data!Q5,"") -> 3 | R5: =IF(Data!R5>0,4-Data!R5,"") -> 3 | S5: =IF(Data!S5>0,4-Data!S5,"") -> 3 | T5: =IF(Data!T5>0,Data!T5-4,"") -> 3 | U5: =IF(Data!U5>0,4-Data!U5,"") -> 3 | V5: =IF(Data!V5>0,Data!V5-4,"") -> 3 | W5: =IF(Data!W5>0,4-Data!W5,"") -> 3 | X5: =IF(Data!X5>0,4-Data!X5,"") -> 3 | Y5: =IF(Data!Y5>0,4-Data!Y5,"") -> 3 | Z5: =IF(Data!Z5>0,Data!Z5-4,"") -> -3 | AC5: =IF(COUNT(A5,L5,N5,P5,X5,Y5)>0,AVERAGE(A5,L5,N5,P5,X5,Y5),"") -> 3 | AD5: =IF(COUNT(B5,D5,M5,U5)>0,AVERAGE(B5,D5,M5,U5),"") -> 3 | AE5: =IF(COUNT(I5,T5,V5,W5)>0,AVERAGE(I5,T5,V5,W5),"") -> 3 | AF5: =IF(COUNT(H5,K5,Q5,S5)>0,AVERAGE(H5,K5,Q5,S5),"") -> 3 | AG5: =IF(COUNT(E5,F5,G5,R5)>0,AVERAGE(E5,F5,G5,R5),"") -> 3 | AH5: =IF(COUNT(C5,J5,O5,Z5)>0,AVERAGE(C5,J5,O5,Z5),"") -> 0
A6: =IF(Data!A6>0,Data!A6-4,"") -> 3 | B6: =IF(Data!B6>0,Data!B6-4,"") -> 3 | C6: =IF(Data!C6>0,4-Data!C6,"") -> 2 | D6: =IF(Data!D6>0,4-Data!D6,"") -> 3 | E6: =IF(Data!E6>0,4-Data!E6,"") -> 3 | F6: =IF(Data!F6>0,Data!F6-4,"") -> 1 | G6: =IF(Data!G6>0,Data!G6-4,"") -> 2 | H6: =IF(Data!H6>0,Data!H6-4,"") -> -2 | I6: =IF(Data!I6>0,4-Data!I6,"") -> 2 | J6: =IF(Data!J6>0,4-Data!J6,"") -> 2 | K6: =IF(Data!K6>0,Data!K6-4,"") -> 1 | L6: =IF(Data!L6>0,4-Data!L6,"") -> 3 | M6: =IF(Data!M6>0,Data!M6-4,"") -> 1 | N6: =IF(Data!N6>0,Data!N6-4,"") -> 2 | O6: =IF(Data!O6>0,Data!O6-4,"") -> 2 | P6: =IF(Data!P6>0,Data!P6-4,"") -> 2 | Q6: =IF(Data!Q6>0,4-Data!Q6,"") -> 2 | R6: =IF(Data!R6>0,4-Data!R6,"") -> 1 | S6: =IF(Data!S6>0,4-Data!S6,"") -> 2 | T6: =IF(Data!T6>0,Data!T6-4,"") -> 2 | U6: =IF(Data!U6>0,4-Data!U6,"") -> 1 | V6: =IF(Data!V6>0,Data!V6-4,"") -> 2 | W6: =IF(Data!W6>0,4-Data!W6,"") -> 2 | X6: =IF(Data!X6>0,4-Data!X6,"") -> 1 | Y6: =IF(Data!Y6>0,4-Data!Y6,"") -> 1 | Z6: =IF(Data!Z6>0,Data!Z6-4,"") -> 2 | AC6: =IF(COUNT(A6,L6,N6,P6,X6,Y6)>0,AVERAGE(A6,L6,N6,P6,X6,Y6),"") -> 2 | AD6: =IF(COUNT(B6,D6,M6,U6)>0,AVERAGE(B6,D6,M6,U6),"") -> 2 | AE6: =IF(COUNT(I6,T6,V6,W6)>0,AVERAGE(I6,T6,V6,W6),"") -> 2 | AF6: =IF(COUNT(H6,K6,Q6,S6)>0,AVERAGE(H6,K6,Q6,S6),"") -> 0.75 | AG6: =IF(COUNT(E6,F6,G6,R6)>0,AVERAGE(E6,F6,G6,R6),"") -> 1.75 | AH6: =IF(COUNT(C6,J6,O6,Z6)>0,AVERAGE(C6,J6,O6,Z6),"") -> 2
A7: =IF(Data!A7>0,Data!A7-4,"") -> 2 | B7: =IF(Data!B7>0,Data!B7-4,"") -> 2 | C7: =IF(Data!C7>0,4-Data!C7,"") -> 0 | D7: =IF(Data!D7>0,4-Data!D7,"") -> 2 | E7: =IF(Data!E7>0,4-Data!E7,"") -> 1 | F7: =IF(Data!F7>0,Data!F7-4,"") -> 0 | G7: =IF(Data!G7>0,Data!G7-4,"") -> 0 | H7: =IF(Data!H7>0,Data!H7-4,"") -> 2 | I7: =IF(Data!I7>0,4-Data!I7,"") -> 2 | J7: =IF(Data!J7>0,4-Data!J7,"") -> 1 | K7: =IF(Data!K7>0,Data!K7-4,"") -> 1 | L7: =IF(Data!L7>0,4-Data!L7,"") -> 3 | M7: =IF(Data!M7>0,Data!M7-4,"") -> 3 | N7: =IF(Data!N7>0,Data!N7-4,"") -> 1 | O7: =IF(Data!O7>0,Data!O7-4,"") -> 2 | P7: =IF(Data!P7>0,Data!P7-4,"") -> 2 | Q7: =IF(Data!Q7>0,4-Data!Q7,"") -> 3 | R7: =IF(Data!R7>0,4-Data!R7,"") -> 0 | S7: =IF(Data!S7>0,4-Data!S7,"") -> 3 | T7: =IF(Data!T7>0,Data!T7-4,"") -> 3 | U7: =IF(Data!U7>0,4-Data!U7,"") -> 3 | V7: =IF(Data!V7>0,Data!V7-4,"") -> 2 | W7: =IF(Data!W7>0,4-Data!W7,"") -> 2 | X7: =IF(Data!X7>0,4-Data!X7,"") -> 0 | Y7: =IF(Data!Y7>0,4-Data!Y7,"") -> 1 | Z7: =IF(Data!Z7>0,Data!Z7-4,"") -> 0 | AC7: =IF(COUNT(A7,L7,N7,P7,X7,Y7)>0,AVERAGE(A7,L7,N7,P7,X7,Y7),"") -> 1.5 | AD7: =IF(COUNT(B7,D7,M7,U7)>0,AVERAGE(B7,D7,M7,U7),"") -> 2.5 | AE7: =IF(COUNT(I7,T7,V7,W7)>0,AVERAGE(I7,T7,V7,W7),"") -> 2.25 | AF7: =IF(COUNT(H7,K7,Q7,S7)>0,AVERAGE(H7,K7,Q7,S7),"") -> 2.25 | AG7: =IF(COUNT(E7,F7,G7,R7)>0,AVERAGE(E7,F7,G7,R7),"") -> 0.25 | AH7: =IF(COUNT(C7,J7,O7,Z7)>0,AVERAGE(C7,J7,O7,Z7),"") -> 0.75
A8: =IF(Data!A8>0,Data!A8-4,"") -> 2 | B8: =IF(Data!B8>0,Data!B8-4,"") -> -1 | C8: =IF(Data!C8>0,4-Data!C8,"") -> 0 | D8: =IF(Data!D8>0,4-Data!D8,"") -> -1 | E8: =IF(Data!E8>0,4-Data!E8,"") -> 2 | F8: =IF(Data!F8>0,Data!F8-4,"") -> 0 | G8: =IF(Data!G8>0,Data!G8-4,"") -> 1 | H8: =IF(Data!H8>0,Data!H8-4,"") -> 1 | I8: =IF(Data!I8>0,4-Data!I8,"") -> 2 | J8: =IF(Data!J8>0,4-Data!J8,"") -> 0 | K8: =IF(Data!K8>0,Data!K8-4,"") -> 1 | L8: =IF(Data!L8>0,4-Data!L8,"") -> 2 | M8: =IF(Data!M8>0,Data!M8-4,"") -> 1 | N8: =IF(Data!N8>0,Data!N8-4,"") -> 1 | O8: =IF(Data!O8>0,Data!O8-4,"") -> 0 | P8: =IF(Data!P8>0,Data!P8-4,"") -> 1 | Q8: =IF(Data!Q8>0,4-Data!Q8,"") -> 2 | R8: =IF(Data!R8>0,4-Data!R8,"") -> 1 | S8: =IF(Data!S8>0,4-Data!S8,"") -> 2 | T8: =IF(Data!T8>0,Data!T8-4,"") -> 2 | U8: =IF(Data!U8>0,4-Data!U8,"") -> 1 | V8: =IF(Data!V8>0,Data!V8-4,"") -> 2 | W8: =IF(Data!W8>0,4-Data!W8,"") -> 2 | X8: =IF(Data!X8>0,4-Data!X8,"") -> 1 | Y8: =IF(Data!Y8>0,4-Data!Y8,"") -> 1 | Z8: =IF(Data!Z8>0,Data!Z8-4,"") -> 0 | AC8: =IF(COUNT(A8,L8,N8,P8,X8,Y8)>0,AVERAGE(A8,L8,N8,P8,X8,Y8),"") -> 1.3333333 | AD8: =IF(COUNT(B8,D8,M8,U8)>0,AVERAGE(B8,D8,M8,U8),"") -> 0 | AE8: =IF(COUNT(I8,T8,V8,W8)>0,AVERAGE(I8,T8,V8,W8),"") -> 2 | AF8: =IF(COUNT(H8,K8,Q8,S8)>0,AVERAGE(H8,K8,Q8,S8),"") -> 1.5 | AG8: =IF(COUNT(E8,F8,G8,R8)>0,AVERAGE(E8,F8,G8,R8),"") -> 1 | AH8: =IF(COUNT(C8,J8,O8,Z8)>0,AVERAGE(C8,J8,O8,Z8),"") -> 0
A9: =IF(Data!A9>0,Data!A9-4,"") -> -1 | B9: =IF(Data!B9>0,Data!B9-4,"") -> 2 | C9: =IF(Data!C9>0,4-Data!C9,"") -> 2 | D9: =IF(Data!D9>0,4-Data!D9,"") -> -3 | E9: =IF(Data!E9>0,4-Data!E9,"") -> 0 | F9: =IF(Data!F9>0,Data!F9-4,"") -> 0 | G9: =IF(Data!G9>0,Data!G9-4,"") -> 0 | H9: =IF(Data!H9>0,Data!H9-4,"") -> 2 | I9: =IF(Data!I9>0,4-Data!I9,"") -> 2 | J9: =IF(Data!J9>0,4-Data!J9,"") -> 0 | K9: =IF(Data!K9>0,Data!K9-4,"") -> 0 | L9: =IF(Data!L9>0,4-Data!L9,"") -> 0 | M9: =IF(Data!M9>0,Data!M9-4,"") -> 0 | N9: =IF(Data!N9>0,Data!N9-4,"") -> -1 | O9: =IF(Data!O9>0,Data!O9-4,"") -> 0 | P9: =IF(Data!P9>0,Data!P9-4,"") -> -1 | Q9: =IF(Data!Q9>0,4-Data!Q9,"") -> -1 | R9: =IF(Data!R9>0,4-Data!R9,"") -> -1 | S9: =IF(Data!S9>0,4-Data!S9,"") -> 0 | T9: =IF(Data!T9>0,Data!T9-4,"") -> 0 | U9: =IF(Data!U9>0,4-Data!U9,"") -> 2 | V9: =IF(Data!V9>0,Data!V9-4,"") -> 2 | W9: =IF(Data!W9>0,4-Data!W9,"") -> 2 | X9: =IF(Data!X9>0,4-Data!X9,"") -> 0 | Y9: =IF(Data!Y9>0,4-Data!Y9,"") -> 1 | Z9: =IF(Data!Z9>0,Data!Z9-4,"") -> 2 | AC9: =IF(COUNT(A9,L9,N9,P9,X9,Y9)>0,AVERAGE(A9,L9,N9,P9,X9,Y9),"") -> -0.33333333 | AD9: =IF(COUNT(B9,D9,M9,U9)>0,AVERAGE(B9,D9,M9,U9),"") -> 0.25 | AE9: =IF(COUNT(I9,T9,V9,W9)>0,AVERAGE(I9,T9,V9,W9),"") -> 1.5 | AF9: =IF(COUNT(H9,K9,Q9,S9)>0,AVERAGE(H9,K9,Q9,S9),"") -> 0.25 | AG9: =IF(COUNT(E9,F9,G9,R9)>0,AVERAGE(E9,F9,G9,R9),"") -> -0.25 | AH9: =IF(COUNT(C9,J9,O9,Z9)>0,AVERAGE(C9,J9,O9,Z9),"") -> 1
A10: =IF(Data!A10>0,Data!A10-4,"") -> 3 | B10: =IF(Data!B10>0,Data!B10-4,"") -> 1 | C10: =IF(Data!C10>0,4-Data!C10,"") -> 0 | D10: =IF(Data!D10>0,4-Data!D10,"") -> -1 | E10: =IF(Data!E10>0,4-Data!E10,"") -> 3 | F10: =IF(Data!F10>0,Data!F10-4,"") -> 0 | G10: =IF(Data!G10>0,Data!G10-4,"") -> 1 | H10: =IF(Data!H10>0,Data!H10-4,"") -> 0 | I10: =IF(Data!I10>0,4-Data!I10,"") -> 1 | J10: =IF(Data!J10>0,4-Data!J10,"") -> 1 | K10: =IF(Data!K10>0,Data!K10-4,"") -> 2 | L10: =IF(Data!L10>0,4-Data!L10,"") -> 3 | M10: =IF(Data!M10>0,Data!M10-4,"") -> 2 | N10: =IF(Data!N10>0,Data!N10-4,"") -> 3 | O10: =IF(Data!O10>0,Data!O10-4,"") -> 0 | P10: =IF(Data!P10>0,Data!P10-4,"") -> 3 | Q10: =IF(Data!Q10>0,4-Data!Q10,"") -> 3 | R10: =IF(Data!R10>0,4-Data!R10,"") -> 1 | S10: =IF(Data!S10>0,4-Data!S10,"") -> 3 | T10: =IF(Data!T10>0,Data!T10-4,"") -> 3 | U10: =IF(Data!U10>0,4-Data!U10,"") -> 2 | V10: =IF(Data!V10>0,Data!V10-4,"") -> 2 | W10: =IF(Data!W10>0,4-Data!W10,"") -> 2 | X10: =IF(Data!X10>0,4-Data!X10,"") -> 0 | Y10: =IF(Data!Y10>0,4-Data!Y10,"") -> 3 | Z10: =IF(Data!Z10>0,Data!Z10-4,"") -> 2 | AC10: =IF(COUNT(A10,L10,N10,P10,X10,Y10)>0,AVERAGE(A10,L10,N10,P10,X10,Y10),"") -> 2.5 | AD10: =IF(COUNT(B10,D10,M10,U10)>0,AVERAGE(B10,D10,M10,U10),"") -> 1 | AE10: =IF(COUNT(I10,T10,V10,W10)>0,AVERAGE(I10,T10,V10,W10),"") -> 2 | AF10: =IF(COUNT(H10,K10,Q10,S10)>0,AVERAGE(H10,K10,Q10,S10),"") -> 2 | AG10: =IF(COUNT(E10,F10,G10,R10)>0,AVERAGE(E10,F10,G10,R10),"") -> 1.25 | AH10: =IF(COUNT(C10,J10,O10,Z10)>0,AVERAGE(C10,J10,O10,Z10),"") -> 0.75
A11: =IF(Data!A11>0,Data!A11-4,"") -> 1 | B11: =IF(Data!B11>0,Data!B11-4,"") -> 2 | C11: =IF(Data!C11>0,4-Data!C11,"") -> 0 | D11: =IF(Data!D11>0,4-Data!D11,"") -> 1 | E11: =IF(Data!E11>0,4-Data!E11,"") -> 3 | F11: =IF(Data!F11>0,Data!F11-4,"") -> 0 | G11: =IF(Data!G11>0,Data!G11-4,"") -> 0 | H11: =IF(Data!H11>0,Data!H11-4,"") -> 2 | I11: =IF(Data!I11>0,4-Data!I11,"") -> 1 | J11: =IF(Data!J11>0,4-Data!J11,"") -> 2 | K11: =IF(Data!K11>0,Data!K11-4,"") -> 0 | L11: =IF(Data!L11>0,4-Data!L11,"") -> 1 | M11: =IF(Data!M11>0,Data!M11-4,"") -> 2 | N11: =IF(Data!N11>0,Data!N11-4,"") -> 0 | O11: =IF(Data!O11>0,Data!O11-4,"") -> 2 | P11: =IF(Data!P11>0,Data!P11-4,"") -> 1 | Q11: =IF(Data!Q11>0,4-Data!Q11,"") -> 3 | R11: =IF(Data!R11>0,4-Data!R11,"") -> 0 | S11: =IF(Data!S11>0,4-Data!S11,"") -> 2 | T11: =IF(Data!T11>0,Data!T11-4,"") -> 1 | U11: =IF(Data!U11>0,4-Data!U11,"") -> 3 | V11: =IF(Data!V11>0,Data!V11-4,"") -> 3 | W11: =IF(Data!W11>0,4-Data!W11,"") -> 1 | X11: =IF(Data!X11>0,4-Data!X11,"") -> 0 | Y11: =IF(Data!Y11>0,4-Data!Y11,"") -> 0 | Z11: =IF(Data!Z11>0,Data!Z11-4,"") -> 1 | AC11: =IF(COUNT(A11,L11,N11,P11,X11,Y11)>0,AVERAGE(A11,L11,N11,P11,X11,Y11),"") -> 0.5 | AD11: =IF(COUNT(B11,D11,M11,U11)>0,AVERAGE(B11,D11,M11,U11),"") -> 2 | AE11: =IF(COUNT(I11,T11,V11,W11)>0,AVERAGE(I11,T11,V11,W11),"") -> 1.5 | AF11: =IF(COUNT(H11,K11,Q11,S11)>0,AVERAGE(H11,K11,Q11,S11),"") -> 1.75 | AG11: =IF(COUNT(E11,F11,G11,R11)>0,AVERAGE(E11,F11,G11,R11),"") -> 0.75 | AH11: =IF(COUNT(C11,J11,O11,Z11)>0,AVERAGE(C11,J11,O11,Z11),"") -> 1.25
A12: =IF(Data!A12>0,Data!A12-4,"") -> 3 | B12: =IF(Data!B12>0,Data!B12-4,"") -> 3 | C12: =IF(Data!C12>0,4-Data!C12,"") -> 3 | D12: =IF(Data!D12>0,4-Data!D12,"") -> 3 | E12: =IF(Data!E12>0,4-Data!E12,"") -> 3 | F12: =IF(Data!F12>0,Data!F12-4,"") -> 1 | G12: =IF(Data!G12>0,Data!G12-4,"") -> 2 | H12: =IF(Data!H12>0,Data!H12-4,"") -> 0 | I12: =IF(Data!I12>0,4-Data!I12,"") -> 3 | J12: =IF(Data!J12>0,4-Data!J12,"") -> 0 | K12: =IF(Data!K12>0,Data!K12-4,"") -> 0 | L12: =IF(Data!L12>0,4-Data!L12,"") -> 3 | M12: =IF(Data!M12>0,Data!M12-4,"") -> 3 | N12: =IF(Data!N12>0,Data!N12-4,"") -> 3 | O12: =IF(Data!O12>0,Data!O12-4,"") -> 3 | P12: =IF(Data!P12>0,Data!P12-4,"") -> 3 | Q12: =IF(Data!Q12>0,4-Data!Q12,"") -> 2 | R12: =IF(Data!R12>0,4-Data!R12,"") -> 0 | S12: =IF(Data!S12>0,4-Data!S12,"") -> 3 | T12: =IF(Data!T12>0,Data!T12-4,"") -> 3 | U12: =IF(Data!U12>0,4-Data!U12,"") -> 2 | V12: =IF(Data!V12>0,Data!V12-4,"") -> 3 | W12: =IF(Data!W12>0,4-Data!W12,"") -> 1 | X12: =IF(Data!X12>0,4-Data!X12,"") -> 3 | Y12: =IF(Data!Y12>0,4-Data!Y12,"") -> 3 | Z12: =IF(Data!Z12>0,Data!Z12-4,"") -> 0 | AC12: =IF(COUNT(A12,L12,N12,P12,X12,Y12)>0,AVERAGE(A12,L12,N12,P12,X12,Y12),"") -> 3 | AD12: =IF(COUNT(B12,D12,M12,U12)>0,AVERAGE(B12,D12,M12,U12),"") -> 2.75 | AE12: =IF(COUNT(I12,T12,V12,W12)>0,AVERAGE(I12,T12,V12,W12),"") -> 2.5 | AF12: =IF(COUNT(H12,K12,Q12,S12)>0,AVERAGE(H12,K12,Q12,S12),"") -> 1.25 | AG12: =IF(COUNT(E12,F12,G12,R12)>0,AVERAGE(E12,F12,G12,R12),"") -> 1.5 | AH12: =IF(COUNT(C12,J12,O12,Z12)>0,AVERAGE(C12,J12,O12,Z12),"") -> 1.5
A13: =IF(Data!A13>0,Data!A13-4,"") -> 2 | B13: =IF(Data!B13>0,Data!B13-4,"") -> 3 | C13: =IF(Data!C13>0,4-Data!C13,"") -> -2 | D13: =IF(Data!D13>0,4-Data!D13,"") -> -2 | E13: =IF(Data!E13>0,4-Data!E13,"") -> -1 | F13: =IF(Data!F13>0,Data!F13-4,"") -> 1 | G13: =IF(Data!G13>0,Data!G13-4,"") -> 1 | H13: =IF(Data!H13>0,Data!H13-4,"") -> -1 | I13: =IF(Data!I13>0,4-Data!I13,"") -> -1 | J13: =IF(Data!J13>0,4-Data!J13,"") -> -2 | K13: =IF(Data!K13>0,Data!K13-4,"") -> 2 | L13: =IF(Data!L13>0,4-Data!L13,"") -> 3 | M13: =IF(Data!M13>0,Data!M13-4,"") -> 3 | N13: =IF(Data!N13>0,Data!N13-4,"") -> 2 | O13: =IF(Data!O13>0,Data!O13-4,"") -> 1 | P13: =IF(Data!P13>0,Data!P13-4,"") -> 2 | Q13: =IF(Data!Q13>0,4-Data!Q13,"") -> 2 | R13: =IF(Data!R13>0,4-Data!R13,"") -> 2 | S13: =IF(Data!S13>0,4-Data!S13,"") -> 2 | T13: =IF(Data!T13>0,Data!T13-4,"") -> 2 | U13: =IF(Data!U13>0,4-Data!U13,"") -> 3 | V13: =IF(Data!V13>0,Data!V13-4,"") -> 3 | W13: =IF(Data!W13>0,4-Data!W13,"") -> 3 | X13: =IF(Data!X13>0,4-Data!X13,"") -> 2 | Y13: =IF(Data!Y13>0,4-Data!Y13,"") -> 3 | Z13: =IF(Data!Z13>0,Data!Z13-4,"") -> -3 | AC13: =IF(COUNT(A13,L13,N13,P13,X13,Y13)>0,AVERAGE(A13,L13,N13,P13,X13,Y13),"") -> 2.3333333 | AD13: =IF(COUNT(B13,D13,M13,U13)>0,AVERAGE(B13,D13,M13,U13),"") -> 1.75 | AE13: =IF(COUNT(I13,T13,V13,W13)>0,AVERAGE(I13,T13,V13,W13),"") -> 1.75 | AF13: =IF(COUNT(H13,K13,Q13,S13)>0,AVERAGE(H13,K13,Q13,S13),"") -> 1.25 | AG13: =IF(COUNT(E13,F13,G13,R13)>0,AVERAGE(E13,F13,G13,R13),"") -> 0.75 | AH13: =IF(COUNT(C13,J13,O13,Z13)>0,AVERAGE(C13,J13,O13,Z13),"") -> -1.5
A14: =IF(Data!A14>0,Data!A14-4,"") -> 1 | B14: =IF(Data!B14>0,Data!B14-4,"") -> 1 | C14: =IF(Data!C14>0,4-Data!C14,"") -> -2 | D14: =IF(Data!D14>0,4-Data!D14,"") -> -2 | E14: =IF(Data!E14>0,4-Data!E14,"") -> 2 | F14: =IF(Data!F14>0,Data!F14-4,"") -> 0 | G14: =IF(Data!G14>0,Data!G14-4,"") -> 1 | H14: =IF(Data!H14>0,Data!H14-4,"") -> -1 | I14: =IF(Data!I14>0,4-Data!I14,"") -> 0 | J14: =IF(Data!J14>0,4-Data!J14,"") -> 2 | K14: =IF(Data!K14>0,Data!K14-4,"") -> 1 | L14: =IF(Data!L14>0,4-Data!L14,"") -> 1 | M14: =IF(Data!M14>0,Data!M14-4,"") -> 1 | N14: =IF(Data!N14>0,Data!N14-4,"") -> 1 | O14: =IF(Data!O14>0,Data!O14-4,"") -> 1 | P14: =IF(Data!P14>0,Data!P14-4,"") -> 1 | Q14: =IF(Data!Q14>0,4-Data!Q14,"") -> 3 | R14: =IF(Data!R14>0,4-Data!R14,"") -> 0 | S14: =IF(Data!S14>0,4-Data!S14,"") -> 2 | T14: =IF(Data!T14>0,Data!T14-4,"") -> 1 | U14: =IF(Data!U14>0,4-Data!U14,"") -> 1 | V14: =IF(Data!V14>0,Data!V14-4,"") -> 1 | W14: =IF(Data!W14>0,4-Data!W14,"") -> -2 | X14: =IF(Data!X14>0,4-Data!X14,"") -> 2 | Y14: =IF(Data!Y14>0,4-Data!Y14,"") -> 2 | Z14: =IF(Data!Z14>0,Data!Z14-4,"") -> 2 | AC14: =IF(COUNT(A14,L14,N14,P14,X14,Y14)>0,AVERAGE(A14,L14,N14,P14,X14,Y14),"") -> 1.3333333 | AD14: =IF(COUNT(B14,D14,M14,U14)>0,AVERAGE(B14,D14,M14,U14),"") -> 0.25 | AE14: =IF(COUNT(I14,T14,V14,W14)>0,AVERAGE(I14,T14,V14,W14),"") -> 0 | AF14: =IF(COUNT(H14,K14,Q14,S14)>0,AVERAGE(H14,K14,Q14,S14),"") -> 1.25 | AG14: =IF(COUNT(E14,F14,G14,R14)>0,AVERAGE(E14,F14,G14,R14),"") -> 0.75 | AH14: =IF(COUNT(C14,J14,O14,Z14)>0,AVERAGE(C14,J14,O14,Z14),"") -> 0.75
A15: =IF(Data!A15>0,Data!A15-4,"") -> 2 | B15: =IF(Data!B15>0,Data!B15-4,"") -> 2 | C15: =IF(Data!C15>0,4-Data!C15,"") -> 0 | D15: =IF(Data!D15>0,4-Data!D15,"") -> 2 | E15: =IF(Data!E15>0,4-Data!E15,"") -> 2 | F15: =IF(Data!F15>0,Data!F15-4,"") -> 1 | G15: =IF(Data!G15>0,Data!G15-4,"") -> 1 | H15: =IF(Data!H15>0,Data!H15-4,"") -> 1 | I15: =IF(Data!I15>0,4-Data!I15,"") -> 0 | J15: =IF(Data!J15>0,4-Data!J15,"") -> 1 | K15: =IF(Data!K15>0,Data!K15-4,"") -> 0 | L15: =IF(Data!L15>0,4-Data!L15,"") -> 2 | M15: =IF(Data!M15>0,Data!M15-4,"") -> 1 | N15: =IF(Data!N15>0,Data!N15-4,"") -> 0 | O15: =IF(Data!O15>0,Data!O15-4,"") -> 0 | P15: =IF(Data!P15>0,Data!P15-4,"") -> 1 | Q15: =IF(Data!Q15>0,4-Data!Q15,"") -> 1 | R15: =IF(Data!R15>0,4-Data!R15,"") -> 0 | S15: =IF(Data!S15>0,4-Data!S15,"") -> 2 | T15: =IF(Data!T15>0,Data!T15-4,"") -> 1 | U15: =IF(Data!U15>0,4-Data!U15,"") -> 2 | V15: =IF(Data!V15>0,Data!V15-4,"") -> 0 | W15: =IF(Data!W15>0,4-Data!W15,"") -> 1 | X15: =IF(Data!X15>0,4-Data!X15,"") -> 1 | Y15: =IF(Data!Y15>0,4-Data!Y15,"") -> 1 | Z15: =IF(Data!Z15>0,Data!Z15-4,"") -> 0 | AC15: =IF(COUNT(A15,L15,N15,P15,X15,Y15)>0,AVERAGE(A15,L15,N15,P15,X15,Y15),"") -> 1.1666667 | AD15: =IF(COUNT(B15,D15,M15,U15)>0,AVERAGE(B15,D15,M15,U15),"") -> 1.75 | AE15: =IF(COUNT(I15,T15,V15,W15)>0,AVERAGE(I15,T15,V15,W15),"") -> 0.5 | AF15: =IF(COUNT(H15,K15,Q15,S15)>0,AVERAGE(H15,K15,Q15,S15),"") -> 1 | AG15: =IF(COUNT(E15,F15,G15,R15)>0,AVERAGE(E15,F15,G15,R15),"") -> 1 | AH15: =IF(COUNT(C15,J15,O15,Z15)>0,AVERAGE(C15,J15,O15,Z15),"") -> 0.25
... A1004: =IF(Data!A1004>0,Data!A1004-4,"") | B1004: =IF(Data!B1004>0,Data!B1004-4,"") | C1004: =IF(Data!C1004>0,4-Data!C1004,"") | D1004: =IF(Data!D1004>0,4-Data!D1004,"") | E1004: =IF(Data!E1004>0,4-Data!E1004,"") | F1004: =IF(Data!F1004>0,Data!F1004-4,"") | G1004: =IF(Data!G1004>0,Data!G1004-4,"") | H1004: =IF(Data!H1004>0,Data!H1004-4,"") | I1004: =IF(Data!I1004>0,4-Data!I1004,"") | J1004: =IF(Data!J1004>0,4-Data!J1004,"") | K1004: =IF(Data!K1004>0,Data!K1004-4,"") | L1004: =IF(Data!L1004>0,4-Data!L1004,"") | M1004: =IF(Data!M1004>0,Data!M1004-4,"") | N1004: =IF(Data!N1004>0,Data!N1004-4,"") | O1004: =IF(Data!O1004>0,Data!O1004-4,"") | P1004: =IF(Data!P1004>0,Data!P1004-4,"") | Q1004: =IF(Data!Q1004>0,4-Data!Q1004,"") | R1004: =IF(Data!R1004>0,4-Data!R1004,"") | S1004: =IF(Data!S1004>0,4-Data!S1004,"") | T1004: =IF(Data!T1004>0,Data!T1004-4,"") | U1004: =IF(Data!U1004>0,4-Data!U1004,"") | V1004: =IF(Data!V1004>0,Data!V1004-4,"") | W1004: =IF(Data!W1004>0,4-Data!W1004,"") | X1004: =IF(Data!X1004>0,4-Data!X1004,"") | Y1004: =IF(Data!Y1004>0,4-Data!Y1004,"") | Z1004: =IF(Data!Z1004>0,Data!Z1004-4,"") | AC1004: =IF(COUNT(A1004,L1004,N1004,P1004,X1004,Y1004)>0,AVERAGE(A1004,L1004,N1004,P1004,X1004,Y1004),"") | AD1004: =IF(COUNT(B1004,D1004,M1004,U1004)>0,AVERAGE(B1004,D1004,M1004,U1004),"") | AE1004: =IF(COUNT(I1004,T1004,V1004,W1004)>0,AVERAGE(I1004,T1004,V1004,W1004),"") | AF1004: =IF(COUNT(H1004,K1004,Q1004,S1004)>0,AVERAGE(H1004,K1004,Q1004,S1004),"") | AG1004: =IF(COUNT(E1004,F1004,G1004,R1004)>0,AVERAGE(E1004,F1004,G1004,R1004),"") | AH1004: =IF(COUNT(C1004,J1004,O1004,Z1004)>0,AVERAGE(C1004,J1004,O1004,Z1004),"")

Sheet Results
A1: Results You can interpret the means of the scales. The UEQ does not produce an overall score for the user experience (you need to use the KPI extension for this). Because of the construction of the questionnaire it does make no sense to built such an overall score (for example by calculating the mean over all scales), since this value can not be interpreted properly. The values for the single items are listed to allow you to detect outliers in the evaluations. If an item shows big deviations to the evaluations of the other items of the same scale this can be a hint that the item is misinterpreted (for example, because of a special context in your evaluation) by a higher number of participants. Values between -0.8and 0.8 represent a more or less neutral evaluation of the corresponding scale, values > 0,8 represent a positive evaluation and values < -0,8 represent a negative evaluation. The range of the scales is between -3 (horribly bad) and +3 (extremely good). But in real applications, in general, only values in a restricted range will be observed. It is due to the calculation of means over a range of different persons with different opinions and answer tendencies (for example the avoidance of extreme answer categories) extremely unlikely to observe values above +2 or below -2. Thus, even a quite good value of +1.5 for a scale looks from the purely visual standpoint on a scale range of -3 to +3 not as positive as it really is. For this reason this sheet contains two variants for the figure that depicts the scale means. Use the figure with the reduced scale -2 to +2 if you communicate the results to persons that have not much knolwedge on the interpretation of this type of data and in situations where you don't want to explain in detail how building mean values and answer tendencies influence the observed data.
A2: Item | B2: Mean | C2: Variance | D2: Std. Dev. | E2: No. | F2: Left | G2: Right | H2: Scale | K2: UEQ Scales (Mean and Variance)
A3: 1 | B3: =AVERAGE(DT!A4:A1004) -> 1.572549 | C3: =VAR(DT!A4:A1004) -> 1.8756214 | D3: =SQRT(C3) -> 1.3695333 | E3: =COUNTA(Data!A4:A1004) -> 255 | F3: =VLOOKUP(Read_First!B5,Items!A1:BA50,2,FALSE) -> annoying | G3: =VLOOKUP(Read_First!B5,Items!A1:BA50,3,FALSE) -> enjoyable | H3: =VLOOKUP(Read_First!B5,Items!A1:BI50,54,FALSE) -> Attractiveness | K3: =VLOOKUP(Read_First!B5,Items!A1:BI50,54,FALSE) -> Attractiveness | L3: =AVERAGE(DT!AC4:AC1004) -> 1.4732026 | M3: =VAR(DT!AC4:AC1004) -> 1.3053814
A4: 2 | B4: =AVERAGE(DT!B4:B1004) -> 1.8862745 | C4: =VAR(DT!B4:B1004) -> 1.7232361 | D4: =SQRT(C4) -> 1.3127209 | E4: =COUNTA(Data!B4:B1004) -> 255 | F4: =VLOOKUP(Read_First!B5,Items!A1:BA50,4,FALSE) -> not understandable | G4: =VLOOKUP(Read_First!B5,Items!A1:BA50,5,FALSE) -> understandable | H4: =VLOOKUP(Read_First!B5,Items!A1:BI50,55,FALSE) -> Perspicuity | K4: =VLOOKUP(Read_First!B5,Items!A1:BI50,55,FALSE) -> Perspicuity | L4: =AVERAGE(DT!AD4:AD1004) -> 1.6421569 | M4: =VAR(DT!AD4:AD1004) -> 1.2949186
A5: 3 | B5: =AVERAGE(DT!C4:C1004) -> 0.78823529 | C5: =VAR(DT!C4:C1004) -> 2.3171839 | D5: =SQRT(C5) -> 1.5222299 | E5: =COUNTA(Data!C4:C1004) -> 255 | F5: =VLOOKUP(Read_First!B5,Items!A1:BA50,6,FALSE) -> creative | G5: =VLOOKUP(Read_First!B5,Items!A1:BA50,7,FALSE) -> dull | H5: =VLOOKUP(Read_First!B5,Items!A1:BI50,59,FALSE) -> Novelty | K5: =VLOOKUP(Read_First!B5,Items!A1:BI50,56,FALSE) -> Efficiency | L5: =AVERAGE(DT!AE4:AE1004) -> 1.6068627 | M5: =VAR(DT!AE4:AE1004) -> 1.0980334
A6: 4 | B6: =AVERAGE(DT!D4:D1004) -> 1.4862745 | C6: =VAR(DT!D4:D1004) -> 2.6523699 | D6: =SQRT(C6) -> 1.6286098 | E6: =COUNTA(Data!D4:D1004) -> 255 | F6: =VLOOKUP(Read_First!B5,Items!A1:BA50,8,FALSE) -> easy to learn | G6: =VLOOKUP(Read_First!B5,Items!A1:BA50,9,FALSE) -> difficult to learn | H6: =VLOOKUP(Read_First!B5,Items!A1:BI50,55,FALSE) -> Perspicuity | K6: =VLOOKUP(Read_First!B5,Items!A1:BI50,57,FALSE) -> Dependability | L6: =AVERAGE(DT!AF4:AF1004) -> 1.2431373 | M6: =VAR(DT!AF4:AF1004) -> 0.82500193
A7: 5 | B7: =AVERAGE(DT!E4:E1004) -> 1.4980392 | C7: =VAR(DT!E4:E1004) -> 2.1879883 | D7: =SQRT(C7) -> 1.479185 | E7: =COUNTA(Data!E4:E1004) -> 255 | F7: =VLOOKUP(Read_First!B5,Items!A1:BA50,10,FALSE) -> valuable | G7: =VLOOKUP(Read_First!B5,Items!A1:BA50,11,FALSE) -> inferior | H7: =VLOOKUP(Read_First!B5,Items!A1:BI50,58,FALSE) -> Stimulation | K7: =VLOOKUP(Read_First!B5,Items!A1:BI50,58,FALSE) -> Stimulation | L7: =AVERAGE(DT!AG4:AG1004) -> 1.1352941 | M7: =VAR(DT!AG4:AG1004) -> 1.1258164
A8: 6 | B8: =AVERAGE(DT!F4:F1004) -> 0.98823529 | C8: =VAR(DT!F4:F1004) -> 1.6573414 | D8: =SQRT(C8) -> 1.2873777 | E8: =COUNTA(Data!F4:F1004) -> 255 | F8: =VLOOKUP(Read_First!B5,Items!A1:BA50,12,FALSE) -> boring | G8: =VLOOKUP(Read_First!B5,Items!A1:BA50,13,FALSE) -> exciting | H8: =VLOOKUP(Read_First!B5,Items!A1:BI50,58,FALSE) -> Stimulation | K8: =VLOOKUP(Read_First!B5,Items!A1:BI50,59,FALSE) -> Novelty | L8: =AVERAGE(DT!AH4:AH1004) -> 0.77352941 | M8: =VAR(DT!AH4:AH1004) -> 1.1652906
A9: 7 | B9: =AVERAGE(DT!G4:G1004) -> 1.227451 | C9: =VAR(DT!G4:G1004) -> 1.8693222 | D9: =SQRT(C9) -> 1.3672316 | E9: =COUNTA(Data!G4:G1004) -> 255 | F9: =VLOOKUP(Read_First!B5,Items!A1:BA50,14,FALSE) -> not interesting | G9: =VLOOKUP(Read_First!B5,Items!A1:BA50,15,FALSE) -> interesting | H9: =VLOOKUP(Read_First!B5,Items!A1:BI50,58,FALSE) -> Stimulation
A10: 8 | B10: =AVERAGE(DT!H4:H1004) -> 0.62352941 | C10: =VAR(DT!H4:H1004) -> 1.8025938 | D10: =SQRT(C10) -> 1.3426071 | E10: =COUNTA(Data!H4:H1004) -> 255 | F10: =VLOOKUP(Read_First!B5,Items!A1:BA50,16,FALSE) -> unpredictable | G10: =VLOOKUP(Read_First!B5,Items!A1:BA50,17,FALSE) -> predictable | H10: =VLOOKUP(Read_First!B5,Items!A1:BI50,57,FALSE) -> Dependability
A11: 9 | B11: =AVERAGE(DT!I4:I1004) -> 1.4313725 | C11: =VAR(DT!I4:I1004) -> 1.8131851 | D11: =SQRT(C11) -> 1.3465456 | E11: =COUNTA(Data!I4:I1004) -> 255 | F11: =VLOOKUP(Read_First!B5,Items!A1:BA50,18,FALSE) -> fast | G11: =VLOOKUP(Read_First!B5,Items!A1:BA50,19,FALSE) -> slow | H11: =VLOOKUP(Read_First!B5,Items!A1:BI50,56,FALSE) -> Efficiency
A12: 10 | B12: =AVERAGE(DT!J4:J1004) -> 0.78823529 | C12: =VAR(DT!J4:J1004) -> 2.2226957 | D12: =SQRT(C12) -> 1.4908708 | E12: =COUNTA(Data!J4:J1004) -> 255 | F12: =VLOOKUP(Read_First!B5,Items!A1:BA50,20,FALSE) -> inventive | G12: =VLOOKUP(Read_First!B5,Items!A1:BA50,21,FALSE) -> conventional | H12: =VLOOKUP(Read_First!B5,Items!A1:BI50,59,FALSE) -> Novelty
A13: 11 | B13: =AVERAGE(DT!K4:K1004) -> 1.0392157 | C13: =VAR(DT!K4:K1004) -> 1.7858577 | D13: =SQRT(C13) -> 1.3363599 | E13: =COUNTA(Data!K4:K1004) -> 255 | F13: =VLOOKUP(Read_First!B5,Items!A1:BA50,22,FALSE) -> obstructive | G13: =VLOOKUP(Read_First!B5,Items!A1:BA50,23,FALSE) -> supportive | H13: =VLOOKUP(Read_First!B5,Items!A1:BI50,57,FALSE) -> Dependability
A14: 12 | B14: =AVERAGE(DT!L4:L1004) -> 1.6862745 | C14: =VAR(DT!L4:L1004) -> 2.0665432 | D14: =SQRT(C14) -> 1.4375476 | E14: =COUNTA(Data!L4:L1004) -> 255 | F14: =VLOOKUP(Read_First!B5,Items!A1:BA50,24,FALSE) -> good | G14: =VLOOKUP(Read_First!B5,Items!A1:BA50,25,FALSE) -> bad | H14: =VLOOKUP(Read_First!B5,Items!A1:BI50,54,FALSE) -> Attractiveness
A15: 13 | B15: =AVERAGE(DT!M4:M1004) -> 1.5254902 | C15: =VAR(DT!M4:M1004) -> 1.9904894 | D15: =SQRT(C15) -> 1.4108471 | E15: =COUNTA(Data!M4:M1004) -> 255 | F15: =VLOOKUP(Read_First!B5,Items!A1:BA50,26,FALSE) -> complicated | G15: =VLOOKUP(Read_First!B5,Items!A1:BA50,27,FALSE) -> easy | H15: =VLOOKUP(Read_First!B5,Items!A1:BI50,55,FALSE) -> Perspicuity
A16: 14 | B16: =AVERAGE(DT!N4:N1004) -> 1.427451 | C16: =VAR(DT!N4:N1004) -> 2.0882199 | D16: =SQRT(C16) -> 1.4450674 | E16: =COUNTA(Data!N4:N1004) -> 255 | F16: =VLOOKUP(Read_First!B5,Items!A1:BA50,28,FALSE) -> unlikable | G16: =VLOOKUP(Read_First!B5,Items!A1:BA50,29,FALSE) -> pleasing | H16: =VLOOKUP(Read_First!B5,Items!A1:BI50,54,FALSE) -> Attractiveness
A17: 15 | B17: =AVERAGE(DT!O4:O1004) -> 0.82745098 | C17: =VAR(DT!O4:O1004) -> 2.1275899 | D17: =SQRT(C17) -> 1.458626 | E17: =COUNTA(Data!O4:O1004) -> 255 | F17: =VLOOKUP(Read_First!B5,Items!A1:BA50,30,FALSE) -> usual | G17: =VLOOKUP(Read_First!B5,Items!A1:BA50,31,FALSE) -> leading edge | H17: =VLOOKUP(Read_First!B5,Items!A1:BI50,59,FALSE) -> Novelty
A18: 16 | B18: =AVERAGE(DT!P4:P1004) -> 1.4784314 | C18: =VAR(DT!P4:P1004) -> 1.9434306 | D18: =SQRT(C18) -> 1.3940698 | E18: =COUNTA(Data!P4:P1004) -> 255 | F18: =VLOOKUP(Read_First!B5,Items!A1:BA50,32,FALSE) -> unpleasant | G18: =VLOOKUP(Read_First!B5,Items!A1:BA50,33,FALSE) -> pleasant | H18: =VLOOKUP(Read_First!B5,Items!A1:BI50,54,FALSE) -> Attractiveness
A19: 17 | B19: =AVERAGE(DT!Q4:Q1004) -> 1.5607843 | C19: =VAR(DT!Q4:Q1004) -> 2.1212907 | D19: =SQRT(C19) -> 1.4564651 | E19: =COUNTA(Data!Q4:Q1004) -> 255 | F19: =VLOOKUP(Read_First!B5,Items!A1:BA50,34,FALSE) -> secure | G19: =VLOOKUP(Read_First!B5,Items!A1:BA50,35,FALSE) -> not secure | H19: =VLOOKUP(Read_First!B5,Items!A1:BI50,57,FALSE) -> Dependability
A20: 18 | B20: =AVERAGE(DT!R4:R1004) -> 0.82745098 | C20: =VAR(DT!R4:R1004) -> 1.7102671 | D20: =SQRT(C20) -> 1.3077718 | E20: =COUNTA(Data!R4:R1004) -> 255 | F20: =VLOOKUP(Read_First!B5,Items!A1:BA50,36,FALSE) -> motivating | G20: =VLOOKUP(Read_First!B5,Items!A1:BA50,37,FALSE) -> demotivating | H20: =VLOOKUP(Read_First!B5,Items!A1:BI50,58,FALSE) -> Stimulation
A21: 19 | B21: =AVERAGE(DT!S4:S1004) -> 1.7490196 | C21: =VAR(DT!S4:S1004) -> 1.8658947 | D21: =SQRT(C21) -> 1.3659776 | E21: =COUNTA(Data!S4:S1004) -> 255 | F21: =VLOOKUP(Read_First!B5,Items!A1:BA50,38,FALSE) -> meets expectations | G21: =VLOOKUP(Read_First!B5,Items!A1:BA50,39,FALSE) -> does not meet expectations | H21: =VLOOKUP(Read_First!B5,Items!A1:BI50,57,FALSE) -> Dependability
A22: 20 | B22: =AVERAGE(DT!T4:T1004) -> 1.7411765 | C22: =VAR(DT!T4:T1004) -> 1.7752663 | D22: =SQRT(C22) -> 1.3323912 | E22: =COUNTA(Data!T4:T1004) -> 255 | F22: =VLOOKUP(Read_First!B5,Items!A1:BA50,40,FALSE) -> inefficient | G22: =VLOOKUP(Read_First!B5,Items!A1:BA50,41,FALSE) -> efficient | H22: =VLOOKUP(Read_First!B5,Items!A1:BI50,56,FALSE) -> Efficiency
A23: 21 | B23: =AVERAGE(DT!U4:U1004) -> 1.6705882 | C23: =VAR(DT!U4:U1004) -> 1.9461788 | D23: =SQRT(C23) -> 1.3950551 | E23: =COUNTA(Data!U4:U1004) -> 255 | F23: =VLOOKUP(Read_First!B5,Items!A1:BA50,42,FALSE) -> clear | G23: =VLOOKUP(Read_First!B5,Items!A1:BA50,43,FALSE) -> confusing | H23: =VLOOKUP(Read_First!B5,Items!A1:BI50,55,FALSE) -> Perspicuity
A24: 22 | B24: =AVERAGE(DT!V4:V1004) -> 1.9294118 | C24: =VAR(DT!V4:V1004) -> 1.2390922 | D24: =SQRT(C24) -> 1.1131452 | E24: =COUNTA(Data!V4:V1004) -> 255 | F24: =VLOOKUP(Read_First!B5,Items!A1:BA50,44,FALSE) -> impractical | G24: =VLOOKUP(Read_First!B5,Items!A1:BA50,45,FALSE) -> practical | H24: =VLOOKUP(Read_First!B5,Items!A1:BI50,56,FALSE) -> Efficiency
A25: 23 | B25: =AVERAGE(DT!W4:W1004) -> 1.3254902 | C25: =VAR(DT!W4:W1004) -> 2.5511193 | D25: =SQRT(C25) -> 1.5972224 | E25: =COUNTA(Data!W4:W1004) -> 255 | F25: =VLOOKUP(Read_First!B5,Items!A1:BA50,46,FALSE) -> organized | G25: =VLOOKUP(Read_First!B5,Items!A1:BA50,47,FALSE) -> cluttered | H25: =VLOOKUP(Read_First!B5,Items!A1:BI50,56,FALSE) -> Efficiency
A26: 24 | B26: =AVERAGE(DT!X4:X1004) -> 1.2039216 | C26: =VAR(DT!X4:X1004) -> 1.7928979 | D26: =SQRT(C26) -> 1.3389914 | E26: =COUNTA(Data!X4:X1004) -> 255 | F26: =VLOOKUP(Read_First!B5,Items!A1:BA50,48,FALSE) -> attractive | G26: =VLOOKUP(Read_First!B5,Items!A1:BA50,49,FALSE) -> unattractive | H26: =VLOOKUP(Read_First!B5,Items!A1:BI50,54,FALSE) -> Attractiveness
A27: 25 | B27: =AVERAGE(DT!Y4:Y1004) -> 1.4705882 | C27: =VAR(DT!Y4:Y1004) -> 1.7698008 | D27: =SQRT(C27) -> 1.3303386 | E27: =COUNTA(Data!Y4:Y1004) -> 255 | F27: =VLOOKUP(Read_First!B5,Items!A1:BA50,50,FALSE) -> friendly | G27: =VLOOKUP(Read_First!B5,Items!A1:BA50,51,FALSE) -> unfriendly | H27: =VLOOKUP(Read_First!B5,Items!A1:BI50,54,FALSE) -> Attractiveness
A28: 26 | B28: =AVERAGE(DT!Z4:Z1004) -> 0.69019608 | C28: =VAR(DT!Z4:Z1004) -> 2.1752972 | D28: =SQRT(C28) -> 1.4748889 | E28: =COUNTA(Data!Z4:Z1004) -> 255 | F28: =VLOOKUP(Read_First!B5,Items!A1:BA50,52,FALSE) -> conservative | G28: =VLOOKUP(Read_First!B5,Items!A1:BA50,53,FALSE) -> innovative | H28: =VLOOKUP(Read_First!B5,Items!A1:BI50,59,FALSE) -> Novelty
K39: Pragmatic and Hedonic Quality
K40: =VLOOKUP(Read_First!B5,Items!A1:BI50,54,FALSE) -> Attractiveness | L40: =AVERAGE(DT!AC4:AC1004) -> 1.4732026
K41: =VLOOKUP(Read_First!B5,Items!A1:BI50,60,FALSE) -> Pragmatic Quality | L41: =(L4+L5+L6)/3 -> 1.4973856
K42: =VLOOKUP(Read_First!B5,Items!A1:BI50,61,FALSE) -> Hedonic Quality | L42: =(L7+L8)/2 -> 0.95441176
K44: The scales of the UEQ can be grouped into pragmatic quality (Perspicuity, Efficiency, Dependability) and hedonic quality (Stimulation, Originality). Pragmatic quality describes task related quality aspects, hedonic quality the non-task related quality aspects. Below the mean of the three pragmatic and hedonic quality aspects is calculated.

Sheet Confidence_Intervals
A1: Confidence intervals for items and scales Here the 5% confidence intervals for the scale means and the means of the single items are shown. The confidence interval is a measure for the precision of the estimation of the scale mean. The smaller the confidence interval is, the higher is the precision of the estimation and the more you can trust your results. The width of the confidence interval depends on the number of available data and on how consistenly the persons judged the evaluated product. The more consistent their opinion is the smaller is the confidence interval. The work sheet Sample_Size helps you to decide how many data you would need to achieve a certain width of the confidence intervall.
A3: Confidence interval (p=0.05) per item | I3: Confidence intervals (p=0.05) per scale
A4: Item | B4: Mean | C4: Std. Dev. | D4: N | E4: Confidence | F4: Confidence interval | I4: Scale | J4: Mean | K4: Std. Dev. | L4: N | M4: Confidence | N4: Confidence interval
A5: 1 | B5: =Results!B3 -> 1.572549 | C5: =Results!D3 -> 1.3695333 | D5: =Results!E3 -> 255 | E5: =CONFIDENCE(0.05, C5, D5) -> 0.16809337 | F5: =B5-E5 -> 1.4044556 | G5: =B5+E5 -> 1.7406424 | I5: =VLOOKUP(Read_First!B5,Items!A1:BI50,54,FALSE) -> Attractiveness | J5: =AVERAGE(DT!AC4:AC1004) -> 1.4732026 | K5: =STDEV(DT!AC4:AC1004) -> 1.1425329 | L5: =MAX(D5:D24) -> 255 | M5: =CONFIDENCE(0.05, K5, L5) -> 0.14023187 | N5: =J5-M5 -> 1.3329707 | O5: =J5+M5 -> 1.6134345
A6: 2 | B6: =Results!B4 -> 1.8862745 | C6: =Results!D4 -> 1.3127209 | D6: =Results!E4 -> 255 | E6: =CONFIDENCE(0.05, C6, D6) -> 0.16112035 | F6: =B6-E6 -> 1.7251542 | G6: =B6+E6 -> 2.0473949 | I6: =VLOOKUP(Read_First!B5,Items!A1:BI50,55,FALSE) -> Perspicuity | J6: =AVERAGE(DT!AD4:AD1004) -> 1.6421569 | K6: =STDEV(DT!AD4:AD1004) -> 1.1379449 | L6: =L5 -> 255 | M6: =CONFIDENCE(0.05, K6, L6) -> 0.13966874 | N6: =J6-M6 -> 1.5024881 | O6: =J6+M6 -> 1.7818256
A7: 3 | B7: =Results!B5 -> 0.78823529 | C7: =Results!D5 -> 1.5222299 | D7: =Results!E5 -> 255 | E7: =CONFIDENCE(0.05, C7, D7) -> 0.18683501 | F7: =B7-E7 -> 0.60140029 | G7: =B7+E7 -> 0.9750703 | I7: =VLOOKUP(Read_First!B5,Items!A1:BI50,56,FALSE) -> Efficiency | J7: =AVERAGE(DT!AE4:AE1004) -> 1.6068627 | K7: =STDEV(DT!AE4:AE1004) -> 1.0478709 | L7: =L6 -> 255 | M7: =CONFIDENCE(0.05, K7, L7) -> 0.12861327 | N7: =J7-M7 -> 1.4782495 | O7: =J7+M7 -> 1.735476
A8: 4 | B8: =Results!B6 -> 1.4862745 | C8: =Results!D6 -> 1.6286098 | D8: =Results!E6 -> 255 | E8: =CONFIDENCE(0.05, C8, D8) -> 0.19989183 | F8: =B8-E8 -> 1.2863827 | G8: =B8+E8 -> 1.6861663 | I8: =VLOOKUP(Read_First!B5,Items!A1:BI50,57,FALSE) -> Dependability | J8: =AVERAGE(DT!AF4:AF1004) -> 1.2431373 | K8: =STDEV(DT!AF4:AF1004) -> 0.90829617 | L8: =L7 -> 255 | M8: =CONFIDENCE(0.05, K8, L8) -> 0.11148219 | N8: =J8-M8 -> 1.1316551 | O8: =J8+M8 -> 1.3546194
A9: 5 | B9: =Results!B7 -> 1.4980392 | C9: =Results!D7 -> 1.479185 | D9: =Results!E7 -> 255 | E9: =CONFIDENCE(0.05, C9, D9) -> 0.18155177 | F9: =B9-E9 -> 1.3164874 | G9: =B9+E9 -> 1.679591 | I9: =VLOOKUP(Read_First!B5,Items!A1:BI50,58,FALSE) -> Stimulation | J9: =AVERAGE(DT!AG4:AG1004) -> 1.1352941 | K9: =STDEV(DT!AG4:AG1004) -> 1.0610449 | L9: =L8 -> 255 | M9: =CONFIDENCE(0.05, K9, L9) -> 0.13023022 | N9: =J9-M9 -> 1.0050639 | O9: =J9+M9 -> 1.2655243
A10: 6 | B10: =Results!B8 -> 0.98823529 | C10: =Results!D8 -> 1.2873777 | D10: =Results!E8 -> 255 | E10: =CONFIDENCE(0.05, C10, D10) -> 0.15800979 | F10: =B10-E10 -> 0.83022551 | G10: =B10+E10 -> 1.1462451 | I10: =VLOOKUP(Read_First!B5,Items!A1:BI50,59,FALSE) -> Novelty | J10: =AVERAGE(DT!AH4:AH1004) -> 0.77352941 | K10: =STDEV(DT!AH4:AH1004) -> 1.0794863 | L10: =L9 -> 255 | M10: =CONFIDENCE(0.05, K10, L10) -> 0.13249367 | N10: =J10-M10 -> 0.64103574 | O10: =J10+M10 -> 0.90602308
A11: 7 | B11: =Results!B9 -> 1.227451 | C11: =Results!D9 -> 1.3672316 | D11: =Results!E9 -> 255 | E11: =CONFIDENCE(0.05, C11, D11) -> 0.16781087 | F11: =B11-E11 -> 1.0596401 | G11: =B11+E11 -> 1.3952618
A12: 8 | B12: =Results!B10 -> 0.62352941 | C12: =Results!D10 -> 1.3426071 | D12: =Results!E10 -> 255 | E12: =CONFIDENCE(0.05, C12, D12) -> 0.16478851 | F12: =B12-E12 -> 0.4587409 | G12: =B12+E12 -> 0.78831793
A13: 9 | B13: =Results!B11 -> 1.4313725 | C13: =Results!D11 -> 1.3465456 | D13: =Results!E11 -> 255 | E13: =CONFIDENCE(0.05, C13, D13) -> 0.16527192 | F13: =B13-E13 -> 1.2661006 | G13: =B13+E13 -> 1.5966445
A14: 10 | B14: =Results!B12 -> 0.78823529 | C14: =Results!D12 -> 1.4908708 | D14: =Results!E12 -> 255 | E14: =CONFIDENCE(0.05, C14, D14) -> 0.18298606 | F14: =B14-E14 -> 0.60524923 | G14: =B14+E14 -> 0.97122135
A15: 11 | B15: =Results!B13 -> 1.0392157 | C15: =Results!D13 -> 1.3363599 | D15: =Results!E13 -> 255 | E15: =CONFIDENCE(0.05, C15, D15) -> 0.16402174 | F15: =B15-E15 -> 0.87519394 | G15: =B15+E15 -> 1.2032374
A16: 12 | B16: =Results!B14 -> 1.6862745 | C16: =Results!D14 -> 1.4375476 | D16: =Results!E14 -> 255 | E16: =CONFIDENCE(0.05, C16, D16) -> 0.1764413 | F16: =B16-E16 -> 1.5098332 | G16: =B16+E16 -> 1.8627158
A17: 13 | B17: =Results!B15 -> 1.5254902 | C17: =Results!D15 -> 1.4108471 | D17: =Results!E15 -> 255 | E17: =CONFIDENCE(0.05, C17, D17) -> 0.17316413 | F17: =B17-E17 -> 1.3523261 | G17: =B17+E17 -> 1.6986543
A18: 14 | B18: =Results!B16 -> 1.427451 | C18: =Results!D16 -> 1.4450674 | D18: =Results!E16 -> 255 | E18: =CONFIDENCE(0.05, C18, D18) -> 0.17736426 | F18: =B18-E18 -> 1.2500867 | G18: =B18+E18 -> 1.6048152
A19: 15 | B19: =Results!B17 -> 0.82745098 | C19: =Results!D17 -> 1.458626 | D19: =Results!E17 -> 255 | E19: =CONFIDENCE(0.05, C19, D19) -> 0.17902841 | F19: =B19-E19 -> 0.64842257 | G19: =B19+E19 -> 1.0064794
A20: 16 | B20: =Results!B18 -> 1.4784314 | C20: =Results!D18 -> 1.3940698 | D20: =Results!E18 -> 255 | E20: =CONFIDENCE(0.05, C20, D20) -> 0.17110493 | F20: =B20-E20 -> 1.3073264 | G20: =B20+E20 -> 1.6495363
A21: 17 | B21: =Results!B19 -> 1.5607843 | C21: =Results!D19 -> 1.4564651 | D21: =Results!E19 -> 255 | E21: =CONFIDENCE(0.05, C21, D21) -> 0.17876319 | F21: =B21-E21 -> 1.3820211 | G21: =B21+E21 -> 1.7395475
A22: 18 | B22: =Results!B20 -> 0.82745098 | C22: =Results!D20 -> 1.3077718 | D22: =Results!E20 -> 255 | E22: =CONFIDENCE(0.05, C22, D22) -> 0.16051291 | F22: =B22-E22 -> 0.66693807 | G22: =B22+E22 -> 0.98796389
... A30: 26 | B30: =Results!B28 -> 0.69019608 | C30: =Results!D28 -> 1.4748889 | D30: =Results!E28 -> 255 | E30: =CONFIDENCE(0.05, C30, D30) -> 0.18102448 | F30: =B30-E30 -> 0.5091716 | G30: =B30+E30 -> 0.87122056

Sheet Answer_Distributions
A1: Distribution of Answers per Item Here you can see the distribution of answers to the single items. If there are items that show a polarization in the answers (many negative and many positve judgements and not much neutral judgements) may help to get deeper insigths concerning aspects of the product that are experienced as quite positive by one subgroup of participants and quite negative by another subgroup.
A2: Nr | B2: Item | C2: 1 | D2: 2 | E2: 3 | F2: 4 | G2: 5 | H2: 6 | I2: 7 | J2: Scale
A3: 1 | B3: =_xlfn.CONCAT(Results!F3,"/",Results!G3) -> annoying/enjoyable | C3: =COUNTIF(DT!A4:A1004,"-3") -> 2 | D3: =COUNTIF(DT!A4:A1004,"-2") -> 12 | E3: =COUNTIF(DT!A4:A1004,"-1") -> 10 | F3: =COUNTIF(DT!A4:A1004,"0") -> 17 | G3: =COUNTIF(DT!A4:A1004,"1") -> 55 | H3: =COUNTIF(DT!A4:A1004,"2") -> 91 | I3: =COUNTIF(DT!A4:A1004,"3") -> 68 | J3: =Results!H3 -> Attractiveness
A4: 2 | B4: =_xlfn.CONCAT(Results!F4,"/",Results!G4) -> not understandable/understandable | C4: =COUNTIF(DT!B4:B1004,"-3") -> 3 | D4: =COUNTIF(DT!B4:B1004,"-2") -> 7 | E4: =COUNTIF(DT!B4:B1004,"-1") -> 7 | F4: =COUNTIF(DT!B4:B1004,"0") -> 12 | G4: =COUNTIF(DT!B4:B1004,"1") -> 42 | H4: =COUNTIF(DT!B4:B1004,"2") -> 83 | I4: =COUNTIF(DT!B4:B1004,"3") -> 101 | J4: =Results!H4 -> Perspicuity
A5: 3 | B5: =_xlfn.CONCAT(Results!G5,"/",Results!F5) -> dull/creative | C5: =COUNTIF(DT!C4:C1004,"-3") -> 7 | D5: =COUNTIF(DT!C4:C1004,"-2") -> 12 | E5: =COUNTIF(DT!C4:C1004,"-1") -> 27 | F5: =COUNTIF(DT!C4:C1004,"0") -> 65 | G5: =COUNTIF(DT!C4:C1004,"1") -> 54 | H5: =COUNTIF(DT!C4:C1004,"2") -> 51 | I5: =COUNTIF(DT!C4:C1004,"3") -> 39 | J5: =Results!H5 -> Novelty
A6: 4 | B6: =_xlfn.CONCAT(Results!G6,"/",Results!F6) -> difficult to learn/easy to learn | C6: =COUNTIF(DT!D4:D1004,"-3") -> 5 | D6: =COUNTIF(DT!D4:D1004,"-2") -> 12 | E6: =COUNTIF(DT!D4:D1004,"-1") -> 30 | F6: =COUNTIF(DT!D4:D1004,"0") -> 10 | G6: =COUNTIF(DT!D4:D1004,"1") -> 31 | H6: =COUNTIF(DT!D4:D1004,"2") -> 84 | I6: =COUNTIF(DT!D4:D1004,"3") -> 83 | J6: =Results!H6 -> Perspicuity
A7: 5 | B7: =_xlfn.CONCAT(Results!G7,"/",Results!F7) -> inferior/valuable | C7: =COUNTIF(DT!E4:E1004,"-3") -> 4 | D7: =COUNTIF(DT!E4:E1004,"-2") -> 11 | E7: =COUNTIF(DT!E4:E1004,"-1") -> 13 | F7: =COUNTIF(DT!E4:E1004,"0") -> 27 | G7: =COUNTIF(DT!E4:E1004,"1") -> 45 | H7: =COUNTIF(DT!E4:E1004,"2") -> 81 | I7: =COUNTIF(DT!E4:E1004,"3") -> 74 | J7: =Results!H7 -> Stimulation
A8: 6 | B8: =_xlfn.CONCAT(Results!F8,"/",Results!G8) -> boring/exciting | C8: =COUNTIF(DT!F4:F1004,"-3") -> 2 | D8: =COUNTIF(DT!F4:F1004,"-2") -> 8 | E8: =COUNTIF(DT!F4:F1004,"-1") -> 14 | F8: =COUNTIF(DT!F4:F1004,"0") -> 70 | G8: =COUNTIF(DT!F4:F1004,"1") -> 66 | H8: =COUNTIF(DT!F4:F1004,"2") -> 63 | I8: =COUNTIF(DT!F4:F1004,"3") -> 32 | J8: =Results!H8 -> Stimulation
A9: 7 | B9: =_xlfn.CONCAT(Results!F9,"/",Results!G9) -> not interesting/interesting | C9: =COUNTIF(DT!G4:G1004,"-3") -> 2 | D9: =COUNTIF(DT!G4:G1004,"-2") -> 13 | E9: =COUNTIF(DT!G4:G1004,"-1") -> 11 | F9: =COUNTIF(DT!G4:G1004,"0") -> 41 | G9: =COUNTIF(DT!G4:G1004,"1") -> 63 | H9: =COUNTIF(DT!G4:G1004,"2") -> 82 | I9: =COUNTIF(DT!G4:G1004,"3") -> 43 | J9: =Results!H9 -> Stimulation
A10: 8 | B10: =_xlfn.CONCAT(Results!F10,"/",Results!G10) -> unpredictable/predictable | C10: =COUNTIF(DT!H4:H1004,"-3") -> 5 | D10: =COUNTIF(DT!H4:H1004,"-2") -> 7 | E10: =COUNTIF(DT!H4:H1004,"-1") -> 33 | F10: =COUNTIF(DT!H4:H1004,"0") -> 84 | G10: =COUNTIF(DT!H4:H1004,"1") -> 51 | H10: =COUNTIF(DT!H4:H1004,"2") -> 55 | I10: =COUNTIF(DT!H4:H1004,"3") -> 20 | J10: =Results!H10 -> Dependability
A11: 9 | B11: =_xlfn.CONCAT(Results!G11,"/",Results!F11) -> slow/fast | C11: =COUNTIF(DT!I4:I1004,"-3") -> 2 | D11: =COUNTIF(DT!I4:I1004,"-2") -> 7 | E11: =COUNTIF(DT!I4:I1004,"-1") -> 19 | F11: =COUNTIF(DT!I4:I1004,"0") -> 27 | G11: =COUNTIF(DT!I4:I1004,"1") -> 49 | H11: =COUNTIF(DT!I4:I1004,"2") -> 98 | I11: =COUNTIF(DT!I4:I1004,"3") -> 53 | J11: =Results!H11 -> Efficiency
A12: 10 | B12: =_xlfn.CONCAT(Results!G12,"/",Results!F12) -> conventional/inventive | C12: =COUNTIF(DT!J4:J1004,"-3") -> 6 | D12: =COUNTIF(DT!J4:J1004,"-2") -> 14 | E12: =COUNTIF(DT!J4:J1004,"-1") -> 28 | F12: =COUNTIF(DT!J4:J1004,"0") -> 55 | G12: =COUNTIF(DT!J4:J1004,"1") -> 61 | H12: =COUNTIF(DT!J4:J1004,"2") -> 59 | I12: =COUNTIF(DT!J4:J1004,"3") -> 32 | J12: =Results!H12 -> Novelty
A13: 11 | B13: =_xlfn.CONCAT(Results!F13,"/",Results!G13) -> obstructive/supportive | C13: =COUNTIF(DT!K4:K1004,"-3") -> 2 | D13: =COUNTIF(DT!K4:K1004,"-2") -> 9 | E13: =COUNTIF(DT!K4:K1004,"-1") -> 15 | F13: =COUNTIF(DT!K4:K1004,"0") -> 64 | G13: =COUNTIF(DT!K4:K1004,"1") -> 65 | H13: =COUNTIF(DT!K4:K1004,"2") -> 61 | I13: =COUNTIF(DT!K4:K1004,"3") -> 39 | J13: =Results!H13 -> Dependability
A14: 12 | B14: =_xlfn.CONCAT(Results!G14,"/",Results!F14) -> bad/good | C14: =COUNTIF(DT!L4:L1004,"-3") -> 3 | D14: =COUNTIF(DT!L4:L1004,"-2") -> 10 | E14: =COUNTIF(DT!L4:L1004,"-1") -> 12 | F14: =COUNTIF(DT!L4:L1004,"0") -> 20 | G14: =COUNTIF(DT!L4:L1004,"1") -> 38 | H14: =COUNTIF(DT!L4:L1004,"2") -> 83 | I14: =COUNTIF(DT!L4:L1004,"3") -> 89 | J14: =Results!H14 -> Attractiveness
A15: 13 | B15: =_xlfn.CONCAT(Results!F15,"/",Results!G15) -> complicated/easy | C15: =COUNTIF(DT!M4:M1004,"-3") -> 3 | D15: =COUNTIF(DT!M4:M1004,"-2") -> 9 | E15: =COUNTIF(DT!M4:M1004,"-1") -> 15 | F15: =COUNTIF(DT!M4:M1004,"0") -> 22 | G15: =COUNTIF(DT!M4:M1004,"1") -> 51 | H15: =COUNTIF(DT!M4:M1004,"2") -> 85 | I15: =COUNTIF(DT!M4:M1004,"3") -> 70 | J15: =Results!H15 -> Perspicuity
A16: 14 | B16: =_xlfn.CONCAT(Results!F16,"/",Results!G16) -> unlikable/pleasing | C16: =COUNTIF(DT!N4:N1004,"-3") -> 6 | D16: =COUNTIF(DT!N4:N1004,"-2") -> 11 | E16: =COUNTIF(DT!N4:N1004,"-1") -> 10 | F16: =COUNTIF(DT!N4:N1004,"0") -> 18 | G16: =COUNTIF(DT!N4:N1004,"1") -> 66 | H16: =COUNTIF(DT!N4:N1004,"2") -> 84 | I16: =COUNTIF(DT!N4:N1004,"3") -> 60 | J16: =Results!H16 -> Attractiveness
A17: 15 | B17: =_xlfn.CONCAT(Results!F17,"/",Results!G17) -> usual/leading edge | C17: =COUNTIF(DT!O4:O1004,"-3") -> 6 | D17: =COUNTIF(DT!O4:O1004,"-2") -> 17 | E17: =COUNTIF(DT!O4:O1004,"-1") -> 21 | F17: =COUNTIF(DT!O4:O1004,"0") -> 47 | G17: =COUNTIF(DT!O4:O1004,"1") -> 68 | H17: =COUNTIF(DT!O4:O1004,"2") -> 72 | I17: =COUNTIF(DT!O4:O1004,"3") -> 24 | J17: =Results!H17 -> Novelty
A18: 16 | B18: =_xlfn.CONCAT(Results!F18,"/",Results!G18) -> unpleasant/pleasant | C18: =COUNTIF(DT!P4:P1004,"-3") -> 4 | D18: =COUNTIF(DT!P4:P1004,"-2") -> 10 | E18: =COUNTIF(DT!P4:P1004,"-1") -> 10 | F18: =COUNTIF(DT!P4:P1004,"0") -> 22 | G18: =COUNTIF(DT!P4:P1004,"1") -> 62 | H18: =COUNTIF(DT!P4:P1004,"2") -> 84 | I18: =COUNTIF(DT!P4:P1004,"3") -> 63 | J18: =Results!H18 -> Attractiveness
A19: 17 | B19: =_xlfn.CONCAT(Results!G19,"/",Results!F19) -> not secure/secure | C19: =COUNTIF(DT!Q4:Q1004,"-3") -> 3 | D19: =COUNTIF(DT!Q4:Q1004,"-2") -> 13 | E19: =COUNTIF(DT!Q4:Q1004,"-1") -> 13 | F19: =COUNTIF(DT!Q4:Q1004,"0") -> 19 | G19: =COUNTIF(DT!Q4:Q1004,"1") -> 40 | H19: =COUNTIF(DT!Q4:Q1004,"2") -> 95 | I19: =COUNTIF(DT!Q4:Q1004,"3") -> 72 | J19: =Results!H19 -> Dependability
A20: 18 | B20: =_xlfn.CONCAT(Results!G20,"/",Results!F20) -> demotivating/motivating | C20: =COUNTIF(DT!R4:R1004,"-3") -> 4 | D20: =COUNTIF(DT!R4:R1004,"-2") -> 8 | E20: =COUNTIF(DT!R4:R1004,"-1") -> 15 | F20: =COUNTIF(DT!R4:R1004,"0") -> 82 | G20: =COUNTIF(DT!R4:R1004,"1") -> 66 | H20: =COUNTIF(DT!R4:R1004,"2") -> 52 | I20: =COUNTIF(DT!R4:R1004,"3") -> 28 | J20: =Results!H20 -> Stimulation
A21: 19 | B21: =_xlfn.CONCAT(Results!G21,"/",Results!F21) -> does not meet expectations/meets expectations | C21: =COUNTIF(DT!S4:S1004,"-3") -> 3 | D21: =COUNTIF(DT!S4:S1004,"-2") -> 10 | E21: =COUNTIF(DT!S4:S1004,"-1") -> 9 | F21: =COUNTIF(DT!S4:S1004,"0") -> 16 | G21: =COUNTIF(DT!S4:S1004,"1") -> 30 | H21: =COUNTIF(DT!S4:S1004,"2") -> 107 | I21: =COUNTIF(DT!S4:S1004,"3") -> 80 | J21: =Results!H21 -> Dependability
A22: 20 | B22: =_xlfn.CONCAT(Results!F22,"/",Results!G22) -> inefficient/efficient | C22: =COUNTIF(DT!T4:T1004,"-3") -> 3 | D22: =COUNTIF(DT!T4:T1004,"-2") -> 8 | E22: =COUNTIF(DT!T4:T1004,"-1") -> 9 | F22: =COUNTIF(DT!T4:T1004,"0") -> 14 | G22: =COUNTIF(DT!T4:T1004,"1") -> 46 | H22: =COUNTIF(DT!T4:T1004,"2") -> 93 | I22: =COUNTIF(DT!T4:T1004,"3") -> 82 | J22: =Results!H22 -> Efficiency
A23: 21 | B23: =_xlfn.CONCAT(Results!G23,"/",Results!F23) -> confusing/clear | C23: =COUNTIF(DT!U4:U1004,"-3") -> 4 | D23: =COUNTIF(DT!U4:U1004,"-2") -> 8 | E23: =COUNTIF(DT!U4:U1004,"-1") -> 12 | F23: =COUNTIF(DT!U4:U1004,"0") -> 15 | G23: =COUNTIF(DT!U4:U1004,"1") -> 46 | H23: =COUNTIF(DT!U4:U1004,"2") -> 90 | I23: =COUNTIF(DT!U4:U1004,"3") -> 80 | J23: =Results!H23 -> Perspicuity
A24: 22 | B24: =_xlfn.CONCAT(Results!F24,"/",Results!G24) -> impractical/practical | C24: =COUNTIF(DT!V4:V1004,"-3") -> 0 | D24: =COUNTIF(DT!V4:V1004,"-2") -> 6 | E24: =COUNTIF(DT!V4:V1004,"-1") -> 4 | F24: =COUNTIF(DT!V4:V1004,"0") -> 17 | G24: =COUNTIF(DT!V4:V1004,"1") -> 32 | H24: =COUNTIF(DT!V4:V1004,"2") -> 112 | I24: =COUNTIF(DT!V4:V1004,"3") -> 84 | J24: =Results!H24 -> Efficiency
A25: 23 | B25: =_xlfn.CONCAT(Results!G25,"/",Results!F25) -> cluttered/organized | C25: =COUNTIF(DT!W4:W1004,"-3") -> 4 | D25: =COUNTIF(DT!W4:W1004,"-2") -> 14 | E25: =COUNTIF(DT!W4:W1004,"-1") -> 25 | F25: =COUNTIF(DT!W4:W1004,"0") -> 24 | G25: =COUNTIF(DT!W4:W1004,"1") -> 46 | H25: =COUNTIF(DT!W4:W1004,"2") -> 69 | I25: =COUNTIF(DT!W4:W1004,"3") -> 73 | J25: =Results!H25 -> Efficiency
A26: 24 | B26: =_xlfn.CONCAT(Results!G26,"/",Results!F26) -> unattractive/attractive | C26: =COUNTIF(DT!X4:X1004,"-3") -> 1 | D26: =COUNTIF(DT!X4:X1004,"-2") -> 8 | E26: =COUNTIF(DT!X4:X1004,"-1") -> 19 | F26: =COUNTIF(DT!X4:X1004,"0") -> 44 | G26: =COUNTIF(DT!X4:X1004,"1") -> 69 | H26: =COUNTIF(DT!X4:X1004,"2") -> 66 | I26: =COUNTIF(DT!X4:X1004,"3") -> 48 | J26: =Results!H26 -> Attractiveness
A27: 25 | B27: =_xlfn.CONCAT(Results!G27,"/",Results!F27) -> unfriendly/friendly | C27: =COUNTIF(DT!Y4:Y1004,"-3") -> 2 | D27: =COUNTIF(DT!Y4:Y1004,"-2") -> 7 | E27: =COUNTIF(DT!Y4:Y1004,"-1") -> 8 | F27: =COUNTIF(DT!Y4:Y1004,"0") -> 41 | G27: =COUNTIF(DT!Y4:Y1004,"1") -> 57 | H27: =COUNTIF(DT!Y4:Y1004,"2") -> 74 | I27: =COUNTIF(DT!Y4:Y1004,"3") -> 66 | J27: =Results!H27 -> Attractiveness
A28: 26 | B28: =_xlfn.CONCAT(Results!F28,"/",Results!G28) -> conservative/innovative | C28: =COUNTIF(DT!Z4:Z1004,"-3") -> 11 | D28: =COUNTIF(DT!Z4:Z1004,"-2") -> 10 | E28: =COUNTIF(DT!Z4:Z1004,"-1") -> 23 | F28: =COUNTIF(DT!Z4:Z1004,"0") -> 69 | G28: =COUNTIF(DT!Z4:Z1004,"1") -> 52 | H28: =COUNTIF(DT!Z4:Z1004,"2") -> 70 | I28: =COUNTIF(DT!Z4:Z1004,"3") -> 20 | J28: =Results!H28 -> Novelty

Sheet Scale_Consistency
A1: Correlations of the items per scale and reliability coefficients Items that belong to the same scale should show in general a high correaltion. Here you can find the correaltions of the items in a scale and some common coefficients, Cronbachs Alpha and Guttmans Lambda2, that are typically used to estimate reliability of a scale.
A3: Cronbachs Alpha-Coefficient The Alpha-Coefficient (Cronbach, 1951) is a measure for the consistency of a scale. There is no generally accepted rule how big the value of the coefficient should be. Many authors assume that a scale should show an alpha value > 0.7 to be considered as sufficiently consistent, but these suggestions are more rules-of-thumb and not based on some sound statistical facts. Thus, from an methodological standpoint such a use of a cut-off criterium is not really well-founded (see for example Schmitt, N., 1996). Especially if you have only a small sample (for example less than 50 answers) the value of the Alpha-Coefficient should be interpreted very carefully. In such cases a low Alpha can result from sampling errors and may not be an indicator for a problem with the scale. If the value of the Alpha-Coefficient for a scale shows a massive deviation from a reasonable target value, for example 0.6 or 0.7, this can be a hint that some items of the scale are in the given context interpreted by several participants in an unexpected way. In such cases please check the single item scores and correlations between the items. This can give a hint if there is maybe a common misinterpretation of an item due to the context of the evaluation. In such cases the corresponding scale should be interpreted very carefully. The 5% confidence interval for the Alpha coefficient is calculated accordingly to Bonett, D.B. (2002), Sample Size Requirements for Testing and Estimating Coefficient Alpha, Journal of Educational and Behavioral Statistics, 27(4), 335-340.
